<link name="base_laser">
<inertial>
<origin xyz="-0.00029774 0.0066667 0.00013047" rpy="0 0 0"/>
<mass value="0.15717"/>
<inertia ixx="6.7885E-05" ixy="-1.3987E-07" ixz="-8.1554E-07" iyy="0.00013173" iyz="-9.0932E-08" izz="7.1972E-05"/>
</inertial>
<visual>
<origin xyz="0 0 0" rpy="0 0 0"/>
<geometry>
<mesh filename="package://toycar/meshes/ydlidar.dae"/>
</geometry>
<material name="">
<color rgba="0.64706 0.61961 0.58824 1"/>
</material>
</visual>
<collision>
<origin xyz="0 0 0" rpy="0 0 0"/>
<geometry>
<mesh filename="package://toycar/meshes/ydlidar.dae"/>
</geometry>
<surface>
<friction>
<ode>
<mu>0</mu>
<mu2>0</mu2>
<slip1>1.0</slip1>
<slip2>1.0</slip2>
</ode>
</friction>
</surface>
</collision>
</link>

<joint name="laser_joint" type="continuous">
<origin xyz="" rpy="0 0 0"/>
<parent link=""/>
<child link=""/>
<axis xyz="0 0 1"/>
</joint>
