<?xml version="1.0" encoding="utf-8"?>
<!-- This URDF was automatically created by SolidWorks to URDF Exporter! Originally created by Stephen Brawner (brawner@gmail.com)
     Commit Version: 1.5.1-0-g916b5db  Build Version: 1.5.7152.31018
     For more information, please see http://wiki.ros.org/sw_urdf_exporter -->
<robot
  name="toycar">

  <link
    name= "base_link">
    <inertial>
      <origin
        xyz="0 0 0"
        rpy="0 0 0" />
        <mass
          value="0" />
        <inertia
            ixx="0"
            ixy="0"
            ixz="0"
            iyy="0"
            iyz="0"
            izz="0" />
    </inertial>
</link>

<link
   name="chassis">
   <inertial>
     <origin
       xyz="0.0241188787709006 0.339275877267529 0.136452263986166"
       rpy="0 0 0" />
     <mass
       value="6.07369475191247" />
     <inertia
       ixx="0.199859996733927"
       ixy="-0.00592977849224241"
       ixz="0.000121044729954876"
       iyy="0.0632502425937498"
       iyz="-0.00019062810770948"
       izz="0.261940285351003" />
   </inertial>
   <visual>
     <origin
       xyz="0 0 0"
       rpy="0 0 0" />
     <geometry>
       <mesh
         filename="package://toycar/meshes/base_link.STL" />
     </geometry>
     <material
       name="">
       <color
         rgba="0.792156862745098 0.819607843137255 0.933333333333333 1" />
     </material>
   </visual>
   <collision>
     <origin
       xyz="0 0 0"
       rpy="0 0 0" />
     <geometry>
       <mesh
         filename="package://toycar/meshes/base_link.STL" />
     </geometry>
   </collision>
 </link>

  <joint name="dummy_joint" type="fixed">
   <origin xyz="0 0 0" rpy="0 0 0" />
     <parent link="base_link" />
     <child link="chassis" />
   </joint>

  <link
    name="rearwheels">
    <inertial>
      <origin
        xyz="0.0111576543182809 0 2.22044604925031E-16"
        rpy="0 0 0" />
      <mass
        value="6.41319229751498" />
      <inertia
        ixx="0.046142380219855"
        ixy="-3.09294080689908E-17"
        ixz="-3.72694496791892E-18"
        iyy="0.039264169278568"
        iyz="-4.25146029492396E-14"
        izz="0.0392641692789027" />
    </inertial>
    <visual>
      <origin
        xyz="0 0 0"
        rpy="0 0 0" />
      <geometry>
        <mesh
          filename="package://toycar/meshes/BackWheels.STL" />
      </geometry>
      <material
        name="">
        <color
          rgba="0.792156862745098 0.819607843137255 0.933333333333333 1" />
      </material>
    </visual>
    <collision>
      <origin
        xyz="0 0 0"
        rpy="0 0 0" />
      <geometry>
        <mesh
          filename="package://toycar/meshes/BackWheels.STL" />
      </geometry>
      <surface>
         <friction>
           <ode>
             <mu>1</mu>
             <mu2>1</mu2>
             <slip1>1.0</slip1>
             <slip2>1.0</slip2>
           </ode>
         </friction>
       </surface>
    </collision>
  </link>
  <joint
    name="rearwheelsjoints"
    type="continuous">
    <origin
      xyz="0.0201777389587092 0.601562335047845 0.0989439985702869"
      rpy="-2.47267900414952 0.000241654950491605 -0.0334899291809578" />
    <parent
      link="chassis" />
    <child
      link="rearwheels" />
    <axis
      xyz="1 0 0" />
  </joint>

  <link
      name="left_frontaxis">
      <inertial>
        <origin
          xyz="0.0598412336760783 0.0127086096639484 0.000767583257256677"
          rpy="0 0 0" />
        <mass
          value="0.0264454012938846" />
        <inertia
          ixx="1.6559252267172E-05"
          ixy="-5.78750185557747E-09"
          ixz="1.13101078043734E-05"
          iyy="5.31172369034804E-05"
          iyz="4.39121888519462E-09"
          izz="3.76887713500634E-05" />
      </inertial>
      <visual>
        <origin
          xyz="0 0 0"
          rpy="0 0 0" />
        <geometry>
          <mesh
            filename="package://toycar/meshes/FrontLeftAxis.STL" />
        </geometry>
        <material
          name="">
          <color
            rgba="0.792156862745098 0.819607843137255 0.933333333333333 1" />
        </material>
      </visual>
      <collision>
        <origin
          xyz="0 0 0"
          rpy="0 0 0" />
        <geometry>
          <mesh
            filename="package://toycar/meshes/FrontLeftAxis.STL" />
        </geometry>
        <surface>
           <friction>
             <ode>
               <mu>0</mu>
               <mu2>0</mu2>
               <slip1>1.0</slip1>
               <slip2>1.0</slip2>
             </ode>
           </friction>
         </surface>
      </collision>
    </link>
    <joint
      name="left_frontaxisjoint"
      type="continuous">
      <origin
        xyz="0.177034738623057 0.0120986853676059 0.193482353849969"
        rpy="-1.51998322811927 1.56357935312313 1.5707963267949" />
      <parent
        link="chassis" />
      <child
        link="left_frontaxis" />
      <axis
        xyz="1 0 0" />
        <limit
          effort ="3" velocity = "100" />
          <joint_properties
            damping = "0" friction="0" />
    </joint>

  <link
    name="Frontleftwheel">
    <inertial>
      <origin
        xyz="3.33066907387547E-16 2.22044604925031E-16 -0.0428558952184119"
        rpy="0 0 0" />
      <mass
        value="2.87379121230964" />
      <inertia
        ixx="0.012756073626077"
        ixy="-1.0842021724855E-19"
        ixz="-6.4290488910871E-17"
        iyy="0.0127560736304397"
        iyz="3.92519302922379E-17"
        izz="0.0229842358703436" />
    </inertial>
    <visual>
      <origin
        xyz="0 0 0"
        rpy="0 0 0" />
      <geometry>
        <mesh
          filename="package://toycar/meshes/FrontLeftWheel.STL" />
      </geometry>
      <material
        name="">
        <color
          rgba="0.792156862745098 0.819607843137255 0.933333333333333 1" />
      </material>
    </visual>
    <collision>
      <origin
        xyz="0 0 0"
        rpy="0 0 0" />
      <geometry>
        <mesh
          filename="package://toycar/meshes/FrontLeftWheel.STL" />
      </geometry>
      <surface>
         <friction>
           <ode>
             <mu>1</mu>
             <mu2>1</mu2>
             <slip1>1.0</slip1>
             <slip2>1.0</slip2>
           </ode>
         </friction>
       </surface>
    </collision>
  </link>
  <joint
    name="FrontLeftWheelJoint"
    type="continuous">
    <origin
      xyz="0.0948370570476664 0.012720099573045 0"
      rpy="0 0 1.69640163131793" />
    <parent
      link="left_frontaxis" />
    <child
      link="Frontleftwheel" />
    <axis
      xyz="0 0 -1" />
      <limit
        effort ="3" velocity = "100" />
        <joint_properties
          damping = "0" friction="0" />
  </joint>





    <link
      name="right_frontaxis">
      <inertial>
        <origin
          xyz="0.0598412338486167 0.012708609118278 0.000767583513073933"
          rpy="0 0 0" />
        <mass
          value="0.0264453987258006" />
        <inertia
          ixx="1.6559252141181E-05"
          ixy="-5.78780484038068E-09"
          ixz="1.13101075264565E-05"
          iyy="5.31172367782986E-05"
          iyz="4.39116256255814E-09"
          izz="3.76887708835088E-05" />
      </inertial>
      <visual>
        <origin
          xyz="0 0 0"
          rpy="0 0 0" />
        <geometry>
          <mesh
            filename="package://toycar/meshes/FrontRightAxies.STL" />
        </geometry>
        <material
          name="">
          <color
            rgba="0.792156862745098 0.819607843137255 0.933333333333333 1" />
        </material>
      </visual>
      <collision>
        <origin
          xyz="0 0 0"
          rpy="0 0 0" />
        <geometry>
          <mesh
            filename="package://toycar/meshes/FrontRightAxies.STL" />
        </geometry>
        <surface>
           <friction>
             <ode>
               <mu>0</mu>
               <mu2>0</mu2>
               <slip1>1.0</slip1>
               <slip2>1.0</slip2>
             </ode>
           </friction>
         </surface>
      </collision>
    </link>
  <joint
    name="right_frontaxisjoint"
    type="continuous">
    <origin
      xyz="-0.166858898254902 -0.00113083578090145 0.193386875086483"
      rpy="1.6216094254706 1.56357935312316 1.57079632679497" />
    <parent
      link="chassis" />
    <child
      link="right_frontaxis" />
    <axis
      xyz="1 0 0" />
      <limit
        effort ="3" velocity = "100" />
        <joint_properties
          damping = "0" friction="0" />
  </joint>
<!-- 5 100/-->

  <link
    name="Frontrightwheel">
    <inertial>
      <origin
        xyz="1.66533453693773E-16 2.22044604925031E-16 -0.0428558952184105"
        rpy="0 0 0" />
      <mass
        value="2.87379121230965" />
      <inertia
        ixx="0.012756073626077"
        ixy="2.47198095326695E-17"
        ixz="-4.89765038014277E-17"
        iyy="0.0127560736304397"
        iyz="-2.31100234164127E-17"
        izz="0.0229842358703436" />
    </inertial>
    <visual>
      <origin
        xyz="0 0 0"
        rpy="0 0 0" />
      <geometry>
        <mesh
          filename="package://toycar/meshes/FrontRightWheel.STL" />
      </geometry>
      <material
        name="">
        <color
          rgba="0.792156862745098 0.819607843137255 0.933333333333333 1" />
      </material>
    </visual>
    <collision>
      <origin
        xyz="0 0 0"
        rpy="0 0 0" />
      <geometry>
        <mesh
          filename="package://toycar/meshes/FrontRightWheel.STL" />
           </geometry>
      <surface>
         <friction>
           <ode>
             <mu>1</mu>
             <mu2>1</mu2>
             <slip1>1.0</slip1>
             <slip2>1.0</slip2>
           </ode>
         </friction>
       </surface>
    </collision>
  </link>
  
<joint
    name="FrontRightWheelJoint"
    type="continuous">
    <origin
      xyz="0.0948370570476667 0.0127200995730463 0"
      rpy="0 0 -1.93863854690982" />
    <parent
      link="right_frontaxis" />
    <child
      link="Frontrightwheel" />
    <axis
      xyz="0 0 1" />
      <limit
        effort ="3" velocity = "100" />
        <joint_properties
          damping = "0" friction="0" />
  </joint>

<transmission name="transmission1">
<type>transmission_interface/SimpleTransmission</type>
<joint name="FrontRightWheelJoint">
<hardwareInterface>hardware_interface/VelocityJointInterface</hardwareInterface>
</joint>
<actuator name="Frontrightwheel">
<mechanicalReduction>1</mechanicalReduction>
<hardwareInterface>hardware_interface/VelocityJointInterface</hardwareInterface>
</actuator>
</transmission>

<transmission name="transmission2">
<type>transmission_interface/SimpleTransmission</type>
<joint name="FrontLeftWheelJoint">
<hardwareInterface>hardware_interface/VelocityJointInterface</hardwareInterface>
</joint>
<actuator name="Frontleftwheel">
<mechanicalReduction>1</mechanicalReduction>
<hardwareInterface>hardware_interface/VelocityJointInterface</hardwareInterface>
</actuator>
</transmission>


 
<transmission name="transmission4">
<type>transmission_interface/SimpleTransmission</type>
<joint name="right_frontaxisjoint">
<hardwareInterface>EffortJointInterface</hardwareInterface>
</joint>
<actuator name="Frontrightwheel_Axis">
<hardwareInterface>EffortJointInterface</hardwareInterface>
<mechanicalReduction>1</mechanicalReduction>
</actuator>
</transmission>

<transmission name="transmission5">
<type>transmission_interface/SimpleTransmission</type>
<joint name="left_frontaxisjoint">
<hardwareInterface>EffortJointInterface</hardwareInterface>
</joint>
<actuator name="Frontleftwheel_Axis">
<hardwareInterface>EffortJointInterface</hardwareInterface>
<mechanicalReduction>1</mechanicalReduction>
</actuator>
</transmission>

<gazebo>
<plugin name="gazebo_ros_control" filename="libgazebo_ros_control.so">
<robotNamespace>/toycar</robotNamespace>
<legacyModeNS>true</legacyModeNS>
</plugin>
</gazebo>


<link 
name="base_laser">
<inertial>
<origin xyz="-0.00029774 0.0066667 0.00013047" rpy="0 0 0"/>
<mass value="0.15717"/>
<inertia ixx="6.7885E-05" ixy="-1.3987E-07" ixz="-8.1554E-07" iyy="0.00013173" iyz="-9.0932E-08" izz="7.1972E-05"/>
</inertial>
<visual>
<origin xyz="0 0 0" rpy="0 0 0"/>
<geometry>
<mesh filename="package://toycar/meshes/ydlidar.dae"/>
</geometry>
<material name="">
<color rgba="0.64706 0.61961 0.58824 1"/>
</material>
</visual>
<collision>
<origin xyz="0 0 0" rpy="0 0 0"/>
<geometry>
<mesh filename="package://toycar/meshes/ydlidar.dae"/>
</geometry>
<surface>
<friction>
<ode>
<mu>0</mu>
<mu2>0</mu2>
<slip1>1.0</slip1>
<slip2>1.0</slip2>
</ode>
</friction>
</surface>
</collision>
</link>
<joint name="laser_joint" type="continuous">
<origin xyz="0 0 0.30" rpy="0 0 0"/>
<parent link="chassis"/>
<child link="base_laser"/>
<axis xyz="0 0 1"/>
</joint>


<gazebo reference="base_laser">

<sensor type="ray" name="base_laser">
<pose>0 0 0 0 0 0</pose>
<visualize>true</visualize>
<update_rate>100</update_rate>
<ray>
<scan>
<horizontal>
<samples>720</samples>
<resolution>1</resolution>
<min_angle>-1.570796</min_angle>
<max_angle>1.570796</max_angle>
</horizontal>
</scan>
<range>
<min>0.10</min>
<max>10.0</max>
<resolution>1</resolution>
</range>
</ray>
<plugin name="libgazebo_ros_laser_lidar" filename="libgazebo_ros_laser.so">
<topicName>/scan</topicName>
<frameName>chassis</frameName>
</plugin>
</sensor>
</gazebo>

<joint name="imu_joint" type="fixed">
<axis xyz="1 0 0"/> 
<origin xyz="0 0 0.19"/>
<parent link="chassis"/>
<child link="imu_link"/>
</joint>


<link name="imu_link">
  <inertial>
    <mass value="0.001"/>
    <origin rpy="0 0 0" xyz="0 0 0"/>
    <inertia ixx="0.0001" ixy="0" ixz="0" iyy="0.000001" iyz="0" izz="0.0001"/>
  </inertial>
  <visual>
    <origin rpy="0 0 0" xyz="0 0 0"/>
    <geometry>
      <box size="0.001 0.001 0.001"/>
    </geometry>
  </visual>
  <collision>
    <origin rpy="0 0 0" xyz="0 0 0"/>
    <geometry>
      <box size=".001 .001 .001"/>
    </geometry>
  </collision>
</link>

<gazebo reference="base_laser">
<gravity>true</gravity>
<sensor name="imu_sensor" type="imu">
<always_on>true</always_on>
<update_rate>100</update_rate>
<visualize>true</visualize>
<topic>__default_topic__</topic>
<plugin filename="libgazebo_ros_imu_sensor.so" name="imu_plugin">
<topicName>imu</topicName>
<bodyName>base_link</bodyName>
<updateRateHZ>10.0</updateRateHZ>
<gaussianNoise>0.0</gaussianNoise>
<xyzOffset>0 0 0</xyzOffset>
<rpyOffset>0 0 0</rpyOffset>
<frameName>imu_link</frameName>
<initialOrientationAsReference>false</initialOrientationAsReference>
</plugin>
<pose>0 0 0 0 0 0</pose>
</sensor>
</gazebo>



</robot>
